PostgreSQL connection failed: (psycopg2.OperationalError) could not translate host name "postgres" to address: nodename nor servname provided, or not known

(Background on this error at: https://sqlalche.me/e/20/e3q8)
Traceback (most recent call last):
  File "/Users/kianwoonwong/.pyenv/versions/3.11.0/lib/python3.11/site-packages/sqlalchemy/engine/base.py", line 145, in __init__
    self._dbapi_connection = engine.raw_connection()
                             ^^^^^^^^^^^^^^^^^^^^^^^
  File "/Users/kianwoonwong/.pyenv/versions/3.11.0/lib/python3.11/site-packages/sqlalchemy/engine/base.py", line 3293, in raw_connection
    return self.pool.connect()
           ^^^^^^^^^^^^^^^^^^^
  File "/Users/kianwoonwong/.pyenv/versions/3.11.0/lib/python3.11/site-packages/sqlalchemy/pool/base.py", line 452, in connect
    return _ConnectionFairy._checkout(self)
           ^^^^^^^^^^^^^^^^^^^^^^^^^^^^^^^^
  File "/Users/kianwoonwong/.pyenv/versions/3.11.0/lib/python3.11/site-packages/sqlalchemy/pool/base.py", line 1269, in _checkout
    fairy = _ConnectionRecord.checkout(pool)
            ^^^^^^^^^^^^^^^^^^^^^^^^^^^^^^^^
  File "/Users/kianwoonwong/.pyenv/versions/3.11.0/lib/python3.11/site-packages/sqlalchemy/pool/base.py", line 716, in checkout
    rec = pool._do_get()
          ^^^^^^^^^^^^^^
  File "/Users/kianwoonwong/.pyenv/versions/3.11.0/lib/python3.11/site-packages/sqlalchemy/pool/impl.py", line 169, in _do_get
    with util.safe_reraise():
  File "/Users/kianwoonwong/.pyenv/versions/3.11.0/lib/python3.11/site-packages/sqlalchemy/util/langhelpers.py", line 146, in __exit__
    raise exc_value.with_traceback(exc_tb)
  File "/Users/kianwoonwong/.pyenv/versions/3.11.0/lib/python3.11/site-packages/sqlalchemy/pool/impl.py", line 167, in _do_get
    return self._create_connection()
           ^^^^^^^^^^^^^^^^^^^^^^^^^
  File "/Users/kianwoonwong/.pyenv/versions/3.11.0/lib/python3.11/site-packages/sqlalchemy/pool/base.py", line 393, in _create_connection
    return _ConnectionRecord(self)
           ^^^^^^^^^^^^^^^^^^^^^^^
  File "/Users/kianwoonwong/.pyenv/versions/3.11.0/lib/python3.11/site-packages/sqlalchemy/pool/base.py", line 678, in __init__
    self.__connect()
  File "/Users/kianwoonwong/.pyenv/versions/3.11.0/lib/python3.11/site-packages/sqlalchemy/pool/base.py", line 902, in __connect
    with util.safe_reraise():
  File "/Users/kianwoonwong/.pyenv/versions/3.11.0/lib/python3.11/site-packages/sqlalchemy/util/langhelpers.py", line 146, in __exit__
    raise exc_value.with_traceback(exc_tb)
  File "/Users/kianwoonwong/.pyenv/versions/3.11.0/lib/python3.11/site-packages/sqlalchemy/pool/base.py", line 898, in __connect
    self.dbapi_connection = connection = pool._invoke_creator(self)
                                         ^^^^^^^^^^^^^^^^^^^^^^^^^^
  File "/Users/kianwoonwong/.pyenv/versions/3.11.0/lib/python3.11/site-packages/sqlalchemy/engine/create.py", line 645, in connect
    return dialect.connect(*cargs, **cparams)
           ^^^^^^^^^^^^^^^^^^^^^^^^^^^^^^^^^^
  File "/Users/kianwoonwong/.pyenv/versions/3.11.0/lib/python3.11/site-packages/sqlalchemy/engine/default.py", line 616, in connect
    return self.loaded_dbapi.connect(*cargs, **cparams)
           ^^^^^^^^^^^^^^^^^^^^^^^^^^^^^^^^^^^^^^^^^^^^
  File "/Users/kianwoonwong/.pyenv/versions/3.11.0/lib/python3.11/site-packages/psycopg2/__init__.py", line 122, in connect
    conn = _connect(dsn, connection_factory=connection_factory, **kwasync)
           ^^^^^^^^^^^^^^^^^^^^^^^^^^^^^^^^^^^^^^^^^^^^^^^^^^^^^^^^^^^^^^^
psycopg2.OperationalError: could not translate host name "postgres" to address: nodename nor servname provided, or not known


The above exception was the direct cause of the following exception:

Traceback (most recent call last):
  File "/Users/kianwoonwong/Downloads/jarvis/app/core/db.py", line 32, in <module>
    with engine.connect() as conn:
         ^^^^^^^^^^^^^^^^
  File "/Users/kianwoonwong/.pyenv/versions/3.11.0/lib/python3.11/site-packages/sqlalchemy/engine/base.py", line 3269, in connect
    return self._connection_cls(self)
           ^^^^^^^^^^^^^^^^^^^^^^^^^^
  File "/Users/kianwoonwong/.pyenv/versions/3.11.0/lib/python3.11/site-packages/sqlalchemy/engine/base.py", line 147, in __init__
    Connection._handle_dbapi_exception_noconnection(
  File "/Users/kianwoonwong/.pyenv/versions/3.11.0/lib/python3.11/site-packages/sqlalchemy/engine/base.py", line 2431, in _handle_dbapi_exception_noconnection
    raise sqlalchemy_exception.with_traceback(exc_info[2]) from e
  File "/Users/kianwoonwong/.pyenv/versions/3.11.0/lib/python3.11/site-packages/sqlalchemy/engine/base.py", line 145, in __init__
    self._dbapi_connection = engine.raw_connection()
                             ^^^^^^^^^^^^^^^^^^^^^^^
  File "/Users/kianwoonwong/.pyenv/versions/3.11.0/lib/python3.11/site-packages/sqlalchemy/engine/base.py", line 3293, in raw_connection
    return self.pool.connect()
           ^^^^^^^^^^^^^^^^^^^
  File "/Users/kianwoonwong/.pyenv/versions/3.11.0/lib/python3.11/site-packages/sqlalchemy/pool/base.py", line 452, in connect
    return _ConnectionFairy._checkout(self)
           ^^^^^^^^^^^^^^^^^^^^^^^^^^^^^^^^
  File "/Users/kianwoonwong/.pyenv/versions/3.11.0/lib/python3.11/site-packages/sqlalchemy/pool/base.py", line 1269, in _checkout
    fairy = _ConnectionRecord.checkout(pool)
            ^^^^^^^^^^^^^^^^^^^^^^^^^^^^^^^^
  File "/Users/kianwoonwong/.pyenv/versions/3.11.0/lib/python3.11/site-packages/sqlalchemy/pool/base.py", line 716, in checkout
    rec = pool._do_get()
          ^^^^^^^^^^^^^^
  File "/Users/kianwoonwong/.pyenv/versions/3.11.0/lib/python3.11/site-packages/sqlalchemy/pool/impl.py", line 169, in _do_get
    with util.safe_reraise():
  File "/Users/kianwoonwong/.pyenv/versions/3.11.0/lib/python3.11/site-packages/sqlalchemy/util/langhelpers.py", line 146, in __exit__
    raise exc_value.with_traceback(exc_tb)
  File "/Users/kianwoonwong/.pyenv/versions/3.11.0/lib/python3.11/site-packages/sqlalchemy/pool/impl.py", line 167, in _do_get
    return self._create_connection()
           ^^^^^^^^^^^^^^^^^^^^^^^^^
  File "/Users/kianwoonwong/.pyenv/versions/3.11.0/lib/python3.11/site-packages/sqlalchemy/pool/base.py", line 393, in _create_connection
    return _ConnectionRecord(self)
           ^^^^^^^^^^^^^^^^^^^^^^^
  File "/Users/kianwoonwong/.pyenv/versions/3.11.0/lib/python3.11/site-packages/sqlalchemy/pool/base.py", line 678, in __init__
    self.__connect()
  File "/Users/kianwoonwong/.pyenv/versions/3.11.0/lib/python3.11/site-packages/sqlalchemy/pool/base.py", line 902, in __connect
    with util.safe_reraise():
  File "/Users/kianwoonwong/.pyenv/versions/3.11.0/lib/python3.11/site-packages/sqlalchemy/util/langhelpers.py", line 146, in __exit__
    raise exc_value.with_traceback(exc_tb)
  File "/Users/kianwoonwong/.pyenv/versions/3.11.0/lib/python3.11/site-packages/sqlalchemy/pool/base.py", line 898, in __connect
    self.dbapi_connection = connection = pool._invoke_creator(self)
                                         ^^^^^^^^^^^^^^^^^^^^^^^^^^
  File "/Users/kianwoonwong/.pyenv/versions/3.11.0/lib/python3.11/site-packages/sqlalchemy/engine/create.py", line 645, in connect
    return dialect.connect(*cargs, **cparams)
           ^^^^^^^^^^^^^^^^^^^^^^^^^^^^^^^^^^
  File "/Users/kianwoonwong/.pyenv/versions/3.11.0/lib/python3.11/site-packages/sqlalchemy/engine/default.py", line 616, in connect
    return self.loaded_dbapi.connect(*cargs, **cparams)
           ^^^^^^^^^^^^^^^^^^^^^^^^^^^^^^^^^^^^^^^^^^^^
  File "/Users/kianwoonwong/.pyenv/versions/3.11.0/lib/python3.11/site-packages/psycopg2/__init__.py", line 122, in connect
    conn = _connect(dsn, connection_factory=connection_factory, **kwasync)
           ^^^^^^^^^^^^^^^^^^^^^^^^^^^^^^^^^^^^^^^^^^^^^^^^^^^^^^^^^^^^^^^
sqlalchemy.exc.OperationalError: (psycopg2.OperationalError) could not translate host name "postgres" to address: nodename nor servname provided, or not known

(Background on this error at: https://sqlalche.me/e/20/e3q8)

During handling of the above exception, another exception occurred:

Traceback (most recent call last):
  File "/Users/kianwoonwong/.pyenv/versions/3.11.0/bin/uvicorn", line 8, in <module>
    sys.exit(main())
             ^^^^^^
  File "/Users/kianwoonwong/.pyenv/versions/3.11.0/lib/python3.11/site-packages/click/core.py", line 1161, in __call__
    return self.main(*args, **kwargs)
           ^^^^^^^^^^^^^^^^^^^^^^^^^^
  File "/Users/kianwoonwong/.pyenv/versions/3.11.0/lib/python3.11/site-packages/click/core.py", line 1082, in main
    rv = self.invoke(ctx)
         ^^^^^^^^^^^^^^^^
  File "/Users/kianwoonwong/.pyenv/versions/3.11.0/lib/python3.11/site-packages/click/core.py", line 1443, in invoke
    return ctx.invoke(self.callback, **ctx.params)
           ^^^^^^^^^^^^^^^^^^^^^^^^^^^^^^^^^^^^^^^
  File "/Users/kianwoonwong/.pyenv/versions/3.11.0/lib/python3.11/site-packages/click/core.py", line 788, in invoke
    return __callback(*args, **kwargs)
           ^^^^^^^^^^^^^^^^^^^^^^^^^^^
  File "/Users/kianwoonwong/.pyenv/versions/3.11.0/lib/python3.11/site-packages/uvicorn/main.py", line 418, in main
    run(
  File "/Users/kianwoonwong/.pyenv/versions/3.11.0/lib/python3.11/site-packages/uvicorn/main.py", line 587, in run
    server.run()
  File "/Users/kianwoonwong/.pyenv/versions/3.11.0/lib/python3.11/site-packages/uvicorn/server.py", line 62, in run
    return asyncio.run(self.serve(sockets=sockets))
           ^^^^^^^^^^^^^^^^^^^^^^^^^^^^^^^^^^^^^^^^
  File "/Users/kianwoonwong/.pyenv/versions/3.11.0/lib/python3.11/asyncio/runners.py", line 190, in run
    return runner.run(main)
           ^^^^^^^^^^^^^^^^
  File "/Users/kianwoonwong/.pyenv/versions/3.11.0/lib/python3.11/asyncio/runners.py", line 118, in run
    return self._loop.run_until_complete(task)
           ^^^^^^^^^^^^^^^^^^^^^^^^^^^^^^^^^^^
  File "uvloop/loop.pyx", line 1518, in uvloop.loop.Loop.run_until_complete
  File "/Users/kianwoonwong/.pyenv/versions/3.11.0/lib/python3.11/site-packages/uvicorn/server.py", line 69, in serve
    config.load()
  File "/Users/kianwoonwong/.pyenv/versions/3.11.0/lib/python3.11/site-packages/uvicorn/config.py", line 458, in load
    self.loaded_app = import_from_string(self.app)
                      ^^^^^^^^^^^^^^^^^^^^^^^^^^^^
  File "/Users/kianwoonwong/.pyenv/versions/3.11.0/lib/python3.11/site-packages/uvicorn/importer.py", line 21, in import_from_string
    module = importlib.import_module(module_str)
             ^^^^^^^^^^^^^^^^^^^^^^^^^^^^^^^^^^^
  File "/Users/kianwoonwong/.pyenv/versions/3.11.0/lib/python3.11/importlib/__init__.py", line 126, in import_module
    return _bootstrap._gcd_import(name[level:], package, level)
           ^^^^^^^^^^^^^^^^^^^^^^^^^^^^^^^^^^^^^^^^^^^^^^^^^^^^
  File "<frozen importlib._bootstrap>", line 1206, in _gcd_import
  File "<frozen importlib._bootstrap>", line 1178, in _find_and_load
  File "<frozen importlib._bootstrap>", line 1149, in _find_and_load_unlocked
  File "<frozen importlib._bootstrap>", line 690, in _load_unlocked
  File "<frozen importlib._bootstrap_external>", line 940, in exec_module
  File "<frozen importlib._bootstrap>", line 241, in _call_with_frames_removed
  File "/Users/kianwoonwong/Downloads/jarvis/app/main.py", line 3, in <module>
    from app.core.db import Base, engine
  File "/Users/kianwoonwong/Downloads/jarvis/app/core/db.py", line 37, in <module>
    raise Exception("PostgreSQL connection required - NO SQLITE FALLBACK!")
Exception: PostgreSQL connection required - NO SQLITE FALLBACK!
